[2025-06-16 12:21:25,835: INFO: main: Welcome to custom logging]
[2025-06-16 23:11:05,760: INFO: main: >>>>>>>> stage Data ingestion stage started <<<<<<<<]
[2025-06-16 23:11:05,772: INFO: common: yaml file: config\config.yaml loaded successfully]
[2025-06-16 23:11:05,773: INFO: common: yaml file: params.yaml loaded successfully]
[2025-06-16 23:11:05,773: ERROR: main: yaml file is empty]
Traceback (most recent call last):
  File "E:\MLOPS\ML_Proj_1\src\datascience\utils\common.py", line 31, in read_yaml
    return ConfigBox(content)
           ^^^^^^^^^^^^^^^^^^
  File "box\\box.py", line 295, in box.box.Box.__init__
box.exceptions.BoxValueError: First argument must be mapping or iterable

During handling of the above exception, another exception occurred:

Traceback (most recent call last):
  File "E:\MLOPS\ML_Proj_1\main.py", line 9, in <module>
    data_ingestion.initiate_data_ingestion()
  File "E:\MLOPS\ML_Proj_1\src\datascience\pipeline\data_ingestion_pipeline.py", line 13, in initiate_data_ingestion
    config=ConfigurationManager()
           ^^^^^^^^^^^^^^^^^^^^^^
  File "E:\MLOPS\ML_Proj_1\src\datascience\config\configuration.py", line 11, in __init__
    self.params = read_yaml(params_filepath)
                  ^^^^^^^^^^^^^^^^^^^^^^^^^^
  File "C:\Users\prana\AppData\Roaming\Python\Python312\site-packages\ensure\main.py", line 872, in __call__
    return_val = self.f(*args, **kwargs)
                 ^^^^^^^^^^^^^^^^^^^^^^^
  File "E:\MLOPS\ML_Proj_1\src\datascience\utils\common.py", line 33, in read_yaml
    raise ValueError("yaml file is empty")
ValueError: yaml file is empty
[2025-06-16 23:12:50,082: INFO: main: >>>>>>>> stage Data ingestion stage started <<<<<<<<]
[2025-06-16 23:12:50,084: INFO: common: yaml file: config\config.yaml loaded successfully]
[2025-06-16 23:12:50,085: INFO: common: yaml file: params.yaml loaded successfully]
[2025-06-16 23:12:50,085: ERROR: main: yaml file is empty]
Traceback (most recent call last):
  File "E:\MLOPS\ML_Proj_1\src\datascience\utils\common.py", line 31, in read_yaml
    return ConfigBox(content)
           ^^^^^^^^^^^^^^^^^^
  File "box\\box.py", line 295, in box.box.Box.__init__
box.exceptions.BoxValueError: First argument must be mapping or iterable

During handling of the above exception, another exception occurred:

Traceback (most recent call last):
  File "E:\MLOPS\ML_Proj_1\main.py", line 9, in <module>
    data_ingestion.initiate_data_ingestion()
  File "E:\MLOPS\ML_Proj_1\src\datascience\pipeline\data_ingestion_pipeline.py", line 13, in initiate_data_ingestion
    config=ConfigurationManager()
           ^^^^^^^^^^^^^^^^^^^^^^
  File "E:\MLOPS\ML_Proj_1\src\datascience\config\configuration.py", line 11, in __init__
    self.params = read_yaml(params_filepath)
                  ^^^^^^^^^^^^^^^^^^^^^^^^^^
  File "C:\Users\prana\AppData\Roaming\Python\Python312\site-packages\ensure\main.py", line 872, in __call__
    return_val = self.f(*args, **kwargs)
                 ^^^^^^^^^^^^^^^^^^^^^^^
  File "E:\MLOPS\ML_Proj_1\src\datascience\utils\common.py", line 33, in read_yaml
    raise ValueError("yaml file is empty")
ValueError: yaml file is empty
[2025-06-16 23:48:12,990: INFO: main: >>>>>>>> stage Data ingestion stage started <<<<<<<<]
[2025-06-16 23:48:12,992: INFO: common: yaml file: config\config.yaml loaded successfully]
[2025-06-16 23:48:12,993: INFO: common: yaml file: params.yaml loaded successfully]
[2025-06-16 23:48:12,994: INFO: common: yaml file: schema.yaml loaded successfully]
[2025-06-16 23:48:12,995: INFO: common: created directory at: artifacts]
[2025-06-16 23:48:12,995: ERROR: main: 'ConfigurationManager' object has no attribute 'get_data_ingestion_config']
Traceback (most recent call last):
  File "E:\MLOPS\ML_Proj_1\main.py", line 9, in <module>
    data_ingestion.initiate_data_ingestion()
  File "E:\MLOPS\ML_Proj_1\src\datascience\pipeline\data_ingestion_pipeline.py", line 14, in initiate_data_ingestion
    data_ingestion_config=config.get_data_ingestion_config()
                          ^^^^^^^^^^^^^^^^^^^^^^^^^^^^^^^^
AttributeError: 'ConfigurationManager' object has no attribute 'get_data_ingestion_config'. Did you mean: 'get_data_ingestion'?
[2025-06-16 23:49:34,355: INFO: main: >>>>>>>> stage Data ingestion stage started <<<<<<<<]
[2025-06-16 23:49:34,357: INFO: common: yaml file: config\config.yaml loaded successfully]
[2025-06-16 23:49:34,357: INFO: common: yaml file: params.yaml loaded successfully]
[2025-06-16 23:49:34,359: INFO: common: yaml file: schema.yaml loaded successfully]
[2025-06-16 23:49:34,361: INFO: common: created directory at: artifacts]
[2025-06-16 23:49:34,361: INFO: common: created directory at: artifacts/data_ingestion]
[2025-06-16 23:49:34,361: ERROR: main: "'ConfigBox' object has no attribute 'root'"]
Traceback (most recent call last):
  File "box\\box.py", line 594, in box.box.Box.__getitem__
KeyError: 'root'

The above exception was the direct cause of the following exception:

Traceback (most recent call last):
  File "box\\box.py", line 633, in box.box.Box.__getattr__
  File "box\\box.py", line 621, in box.box.Box.__getitem__
box.exceptions.BoxKeyError: "'root'"

During handling of the above exception, another exception occurred:

Traceback (most recent call last):
  File "box\\box.py", line 635, in box.box.Box.__getattr__
AttributeError: 'ConfigBox' object has no attribute 'root'

The above exception was the direct cause of the following exception:

Traceback (most recent call last):
  File "box\\config_box.py", line 29, in box.config_box.ConfigBox.__getattr__
  File "box\\box.py", line 649, in box.box.Box.__getattr__
box.exceptions.BoxKeyError: "'ConfigBox' object has no attribute 'root'"

During handling of the above exception, another exception occurred:

Traceback (most recent call last):
  File "box\\box.py", line 594, in box.box.Box.__getitem__
KeyError: 'root'

The above exception was the direct cause of the following exception:

Traceback (most recent call last):
  File "box\\box.py", line 633, in box.box.Box.__getattr__
  File "box\\box.py", line 621, in box.box.Box.__getitem__
box.exceptions.BoxKeyError: "'root'"

During handling of the above exception, another exception occurred:

Traceback (most recent call last):
  File "box\\box.py", line 635, in box.box.Box.__getattr__
AttributeError: 'ConfigBox' object has no attribute 'root'

The above exception was the direct cause of the following exception:

Traceback (most recent call last):
  File "E:\MLOPS\ML_Proj_1\main.py", line 9, in <module>
    data_ingestion.initiate_data_ingestion()
  File "E:\MLOPS\ML_Proj_1\src\datascience\pipeline\data_ingestion_pipeline.py", line 14, in initiate_data_ingestion
    data_ingestion_config=config.get_data_ingestion_config()
                          ^^^^^^^^^^^^^^^^^^^^^^^^^^^^^^^^^^
  File "E:\MLOPS\ML_Proj_1\src\datascience\config\configuration.py", line 19, in get_data_ingestion_config
    root_dir = config.root.dir,
               ^^^^^^^^^^^
  File "box\\config_box.py", line 31, in box.config_box.ConfigBox.__getattr__
  File "box\\box.py", line 649, in box.box.Box.__getattr__
box.exceptions.BoxKeyError: "'ConfigBox' object has no attribute 'root'"
[2025-06-16 23:54:38,013: INFO: main: >>>>>>>> stage Data ingestion stage started <<<<<<<<]
[2025-06-16 23:54:38,013: INFO: common: yaml file: config\config.yaml loaded successfully]
[2025-06-16 23:54:38,013: INFO: common: yaml file: params.yaml loaded successfully]
[2025-06-16 23:54:38,013: INFO: common: yaml file: schema.yaml loaded successfully]
[2025-06-16 23:54:38,013: INFO: common: created directory at: artifacts]
[2025-06-16 23:54:38,013: INFO: common: created directory at: artifacts/data_ingestion]
[2025-06-16 23:54:38,013: ERROR: main: "'ConfigBox' object has no attribute 'root'"]
Traceback (most recent call last):
  File "box\\box.py", line 594, in box.box.Box.__getitem__
KeyError: 'root'

The above exception was the direct cause of the following exception:

Traceback (most recent call last):
  File "box\\box.py", line 633, in box.box.Box.__getattr__
  File "box\\box.py", line 621, in box.box.Box.__getitem__
box.exceptions.BoxKeyError: "'root'"

During handling of the above exception, another exception occurred:

Traceback (most recent call last):
  File "box\\box.py", line 635, in box.box.Box.__getattr__
AttributeError: 'ConfigBox' object has no attribute 'root'

The above exception was the direct cause of the following exception:

Traceback (most recent call last):
  File "box\\config_box.py", line 29, in box.config_box.ConfigBox.__getattr__
  File "box\\box.py", line 649, in box.box.Box.__getattr__
box.exceptions.BoxKeyError: "'ConfigBox' object has no attribute 'root'"

During handling of the above exception, another exception occurred:

Traceback (most recent call last):
  File "box\\box.py", line 594, in box.box.Box.__getitem__
KeyError: 'root'

The above exception was the direct cause of the following exception:

Traceback (most recent call last):
  File "box\\box.py", line 633, in box.box.Box.__getattr__
  File "box\\box.py", line 621, in box.box.Box.__getitem__
box.exceptions.BoxKeyError: "'root'"

During handling of the above exception, another exception occurred:

Traceback (most recent call last):
  File "box\\box.py", line 635, in box.box.Box.__getattr__
AttributeError: 'ConfigBox' object has no attribute 'root'

The above exception was the direct cause of the following exception:

Traceback (most recent call last):
  File "E:\MLOPS\ML_Proj_1\main.py", line 9, in <module>
    data_ingestion.initiate_data_ingestion()
  File "E:\MLOPS\ML_Proj_1\src\datascience\pipeline\data_ingestion_pipeline.py", line 14, in initiate_data_ingestion
    data_ingestion_config=config.get_data_ingestion_config()
                          ^^^^^^^^^^^^^^^^^^^^^^^^^^^^^^^^^^
  File "E:\MLOPS\ML_Proj_1\src\datascience\config\configuration.py", line 19, in get_data_ingestion_config
    root_dir = config.root.dir,
               ^^^^^^^^^^^
  File "box\\config_box.py", line 31, in box.config_box.ConfigBox.__getattr__
  File "box\\box.py", line 649, in box.box.Box.__getattr__
box.exceptions.BoxKeyError: "'ConfigBox' object has no attribute 'root'"
[2025-06-16 23:58:50,741: INFO: main: >>>>>>>> stage Data ingestion stage started <<<<<<<<]
[2025-06-16 23:58:50,741: INFO: common: yaml file: config\config.yaml loaded successfully]
[2025-06-16 23:58:50,741: INFO: common: yaml file: params.yaml loaded successfully]
[2025-06-16 23:58:50,741: INFO: common: yaml file: schema.yaml loaded successfully]
[2025-06-16 23:58:50,741: INFO: common: created directory at: artifacts]
[2025-06-16 23:58:50,741: INFO: common: created directory at: artifacts/data_ingestion]
[2025-06-16 23:58:50,741: ERROR: main: 'NoneType' object has no attribute 'local_data_file']
Traceback (most recent call last):
  File "E:\MLOPS\ML_Proj_1\main.py", line 9, in <module>
    data_ingestion.initiate_data_ingestion()
  File "E:\MLOPS\ML_Proj_1\src\datascience\pipeline\data_ingestion_pipeline.py", line 16, in initiate_data_ingestion
    data_ingestion.download_file()
  File "E:\MLOPS\ML_Proj_1\src\datascience\components\data_ingestion.py", line 16, in download_file
    if not os.path.exists(self.config.local_data_file):
                          ^^^^^^^^^^^^^^^^^^^^^^^^^^^
AttributeError: 'NoneType' object has no attribute 'local_data_file'
[2025-06-17 00:04:36,999: INFO: main: >>>>>>>> stage Data ingestion stage started <<<<<<<<]
[2025-06-17 00:04:36,999: INFO: common: yaml file: config\config.yaml loaded successfully]
[2025-06-17 00:04:36,999: INFO: common: yaml file: params.yaml loaded successfully]
[2025-06-17 00:04:36,999: INFO: common: yaml file: schema.yaml loaded successfully]
[2025-06-17 00:04:37,014: INFO: common: created directory at: artifacts]
[2025-06-17 00:04:37,014: INFO: common: created directory at: artifacts/data_ingestion]
[2025-06-17 00:04:38,263: INFO: data_ingestion: artifacts/data_ingestion/data.zip download! with following info: 
Connection: close
Content-Length: 23329
Cache-Control: max-age=300
Content-Security-Policy: default-src 'none'; style-src 'unsafe-inline'; sandbox
Content-Type: application/zip
ETag: "c69888a4ae59bc5a893392785a938ccd4937981c06ba8a9d6a21aa52b4ab5b6e"
Strict-Transport-Security: max-age=31536000
X-Content-Type-Options: nosniff
X-Frame-Options: deny
X-XSS-Protection: 1; mode=block
X-GitHub-Request-Id: B6BC:B5609:43934:A4C92:685063BC
Accept-Ranges: bytes
Date: Mon, 16 Jun 2025 18:34:37 GMT
Via: 1.1 varnish
X-Served-By: cache-maa10226-MAA
X-Cache: MISS
X-Cache-Hits: 0
X-Timer: S1750098877.281514,VS0,VE307
Vary: Authorization,Accept-Encoding
Access-Control-Allow-Origin: *
Cross-Origin-Resource-Policy: cross-origin
X-Fastly-Request-ID: 5b71b79327efda4f812e004b925945161e42a4cb
Expires: Mon, 16 Jun 2025 18:39:37 GMT
Source-Age: 0

]
[2025-06-17 00:04:38,442: INFO: main: >>>>> stage Data ingestion stage completed <<<<<<<

x==========x]
[2025-06-17 12:51:52,916: INFO: main: >>>>>>>> stage Data ingestion stage started <<<<<<<<]
[2025-06-17 12:51:52,918: INFO: common: yaml file: config\config.yaml loaded successfully]
[2025-06-17 12:51:52,921: INFO: common: yaml file: params.yaml loaded successfully]
[2025-06-17 12:51:52,923: INFO: common: yaml file: schema.yaml loaded successfully]
[2025-06-17 12:51:52,923: INFO: common: created directory at: artifacts]
[2025-06-17 12:51:52,923: INFO: common: created directory at: artifacts/data_ingestion]
[2025-06-17 12:51:52,924: INFO: data_ingestion: File already exists]
[2025-06-17 12:51:52,932: INFO: main: >>>>> stage Data ingestion stage completed <<<<<<<

x==========x]
[2025-06-17 12:52:42,263: INFO: utils: NumExpr defaulting to 8 threads.]
[2025-06-17 12:56:29,181: INFO: utils: NumExpr defaulting to 8 threads.]
[2025-06-17 12:56:29,400: INFO: main: >>>>>>>> stage Data ingestion stage started <<<<<<<<]
[2025-06-17 12:56:29,401: INFO: common: yaml file: config\config.yaml loaded successfully]
[2025-06-17 12:56:29,402: INFO: common: yaml file: params.yaml loaded successfully]
[2025-06-17 12:56:29,403: INFO: common: yaml file: schema.yaml loaded successfully]
[2025-06-17 12:56:29,403: INFO: common: created directory at: artifacts]
[2025-06-17 12:56:29,404: INFO: common: created directory at: artifacts/data_ingestion]
[2025-06-17 12:56:29,404: INFO: data_ingestion: File already exists]
[2025-06-17 12:56:29,406: INFO: main: >>>>> stage Data ingestion stage completed <<<<<<<

x==========x]
[2025-06-17 12:56:29,406: INFO: main: >>>>>>>> stage Data validation stage started <<<<<<<<]
[2025-06-17 12:56:29,407: INFO: common: yaml file: config\config.yaml loaded successfully]
[2025-06-17 12:56:29,408: INFO: common: yaml file: params.yaml loaded successfully]
[2025-06-17 12:56:29,410: INFO: common: yaml file: schema.yaml loaded successfully]
[2025-06-17 12:56:29,411: INFO: common: created directory at: artifacts]
[2025-06-17 12:56:29,411: ERROR: main: "'ConfigBox' object has no attribute 'data_valdation'"]
Traceback (most recent call last):
  File "box\\box.py", line 594, in box.box.Box.__getitem__
KeyError: 'data_valdation'

The above exception was the direct cause of the following exception:

Traceback (most recent call last):
  File "box\\box.py", line 633, in box.box.Box.__getattr__
  File "box\\box.py", line 621, in box.box.Box.__getitem__
box.exceptions.BoxKeyError: "'data_valdation'"

During handling of the above exception, another exception occurred:

Traceback (most recent call last):
  File "box\\box.py", line 635, in box.box.Box.__getattr__
AttributeError: 'ConfigBox' object has no attribute 'data_valdation'. Did you mean: 'data_validation'?

The above exception was the direct cause of the following exception:

Traceback (most recent call last):
  File "box\\config_box.py", line 29, in box.config_box.ConfigBox.__getattr__
  File "box\\box.py", line 649, in box.box.Box.__getattr__
box.exceptions.BoxKeyError: "'ConfigBox' object has no attribute 'data_valdation'"

During handling of the above exception, another exception occurred:

Traceback (most recent call last):
  File "box\\box.py", line 594, in box.box.Box.__getitem__
KeyError: 'data_valdation'

The above exception was the direct cause of the following exception:

Traceback (most recent call last):
  File "box\\box.py", line 633, in box.box.Box.__getattr__
  File "box\\box.py", line 621, in box.box.Box.__getitem__
box.exceptions.BoxKeyError: "'data_valdation'"

During handling of the above exception, another exception occurred:

Traceback (most recent call last):
  File "box\\box.py", line 635, in box.box.Box.__getattr__
AttributeError: 'ConfigBox' object has no attribute 'data_valdation'. Did you mean: 'data_validation'?

The above exception was the direct cause of the following exception:

Traceback (most recent call last):
  File "E:\MLOPS\ML_Proj_1\main.py", line 20, in <module>
    data_ingestion.initiate_data_validation()
  File "E:\MLOPS\ML_Proj_1\src\datascience\pipeline\data_validation_pipeline.py", line 14, in initiate_data_validation
    data_validation_config = config.get_data_validation_config()
                             ^^^^^^^^^^^^^^^^^^^^^^^^^^^^^^^^^^^
  File "E:\MLOPS\ML_Proj_1\src\datascience\config\configuration.py", line 28, in get_data_validation_config
    config = self.config.data_valdation
             ^^^^^^^^^^^^^^^^^^^^^^^^^^
  File "box\\config_box.py", line 31, in box.config_box.ConfigBox.__getattr__
  File "box\\box.py", line 649, in box.box.Box.__getattr__
box.exceptions.BoxKeyError: "'ConfigBox' object has no attribute 'data_valdation'". Did you mean: 'data_validation'?
[2025-06-17 12:57:58,250: INFO: utils: NumExpr defaulting to 8 threads.]
[2025-06-17 12:57:58,471: INFO: main: >>>>>>>> stage Data ingestion stage started <<<<<<<<]
[2025-06-17 12:57:58,473: INFO: common: yaml file: config\config.yaml loaded successfully]
[2025-06-17 12:57:58,473: INFO: common: yaml file: params.yaml loaded successfully]
[2025-06-17 12:57:58,475: INFO: common: yaml file: schema.yaml loaded successfully]
[2025-06-17 12:57:58,475: INFO: common: created directory at: artifacts]
[2025-06-17 12:57:58,475: INFO: common: created directory at: artifacts/data_ingestion]
[2025-06-17 12:57:58,476: INFO: data_ingestion: File already exists]
[2025-06-17 12:57:58,478: INFO: main: >>>>> stage Data ingestion stage completed <<<<<<<

x==========x]
[2025-06-17 12:57:58,478: INFO: main: >>>>>>>> stage Data validation stage started <<<<<<<<]
[2025-06-17 12:57:58,479: INFO: common: yaml file: config\config.yaml loaded successfully]
[2025-06-17 12:57:58,479: INFO: common: yaml file: params.yaml loaded successfully]
[2025-06-17 12:57:58,481: INFO: common: yaml file: schema.yaml loaded successfully]
[2025-06-17 12:57:58,481: INFO: common: created directory at: artifacts]
[2025-06-17 12:57:58,481: INFO: common: created directory at: artifacts/data_validation]
[2025-06-17 12:57:58,482: ERROR: main: name 'pd' is not defined]
Traceback (most recent call last):
  File "E:\MLOPS\ML_Proj_1\main.py", line 20, in <module>
    data_ingestion.initiate_data_validation()
  File "E:\MLOPS\ML_Proj_1\src\datascience\pipeline\data_validation_pipeline.py", line 16, in initiate_data_validation
    data_validation.validate_all_columns()
  File "E:\MLOPS\ML_Proj_1\src\datascience\components\data_validation.py", line 33, in validate_all_columns
    raise e
  File "E:\MLOPS\ML_Proj_1\src\datascience\components\data_validation.py", line 14, in validate_all_columns
    data = pd.read_csv(self.config.unzip_data_dir)
           ^^
NameError: name 'pd' is not defined
[2025-06-17 12:58:40,571: INFO: utils: NumExpr defaulting to 8 threads.]
[2025-06-17 12:58:40,780: INFO: main: >>>>>>>> stage Data ingestion stage started <<<<<<<<]
[2025-06-17 12:58:40,781: INFO: common: yaml file: config\config.yaml loaded successfully]
[2025-06-17 12:58:40,782: INFO: common: yaml file: params.yaml loaded successfully]
[2025-06-17 12:58:40,783: INFO: common: yaml file: schema.yaml loaded successfully]
[2025-06-17 12:58:40,784: INFO: common: created directory at: artifacts]
[2025-06-17 12:58:40,784: INFO: common: created directory at: artifacts/data_ingestion]
[2025-06-17 12:58:40,784: INFO: data_ingestion: File already exists]
[2025-06-17 12:58:40,787: INFO: main: >>>>> stage Data ingestion stage completed <<<<<<<

x==========x]
[2025-06-17 12:58:40,787: INFO: main: >>>>>>>> stage Data validation stage started <<<<<<<<]
[2025-06-17 12:58:40,788: INFO: common: yaml file: config\config.yaml loaded successfully]
[2025-06-17 12:58:40,789: INFO: common: yaml file: params.yaml loaded successfully]
[2025-06-17 12:58:40,790: INFO: common: yaml file: schema.yaml loaded successfully]
[2025-06-17 12:58:40,790: INFO: common: created directory at: artifacts]
[2025-06-17 12:58:40,791: INFO: common: created directory at: artifacts/data_validation]
[2025-06-17 12:58:40,805: INFO: main: >>>>> stage Data validation stage completed <<<<<<<

x==========x]
[2025-06-17 15:03:35,361: INFO: utils: NumExpr defaulting to 8 threads.]
[2025-06-17 15:03:41,477: INFO: main: >>>>>>>> stage Data ingestion stage started <<<<<<<<]
[2025-06-17 15:03:41,477: INFO: common: yaml file: config\config.yaml loaded successfully]
[2025-06-17 15:03:41,483: INFO: common: yaml file: params.yaml loaded successfully]
[2025-06-17 15:03:41,483: INFO: common: yaml file: schema.yaml loaded successfully]
[2025-06-17 15:03:41,483: INFO: common: created directory at: artifacts]
[2025-06-17 15:03:41,483: INFO: common: created directory at: artifacts/data_ingestion]
[2025-06-17 15:03:41,483: INFO: data_ingestion: File already exists]
[2025-06-17 15:03:41,483: INFO: main: >>>>> stage Data ingestion stage completed <<<<<<<

x==========x]
[2025-06-17 15:03:41,483: INFO: main: >>>>>>>> stage Data validation stage started <<<<<<<<]
[2025-06-17 15:03:41,492: INFO: common: yaml file: config\config.yaml loaded successfully]
[2025-06-17 15:03:41,494: INFO: common: yaml file: params.yaml loaded successfully]
[2025-06-17 15:03:41,495: INFO: common: yaml file: schema.yaml loaded successfully]
[2025-06-17 15:03:41,495: INFO: common: created directory at: artifacts]
[2025-06-17 15:03:41,495: INFO: common: created directory at: artifacts/data_validation]
[2025-06-17 15:03:41,515: INFO: main: >>>>> stage Data validation stage completed <<<<<<<

x==========x]
[2025-06-17 15:03:41,515: INFO: main: >>>>>>>> stage Data transformation stage started <<<<<<<<]
[2025-06-17 15:03:41,518: INFO: common: yaml file: config\config.yaml loaded successfully]
[2025-06-17 15:03:41,518: INFO: common: yaml file: params.yaml loaded successfully]
[2025-06-17 15:03:41,521: INFO: common: yaml file: schema.yaml loaded successfully]
[2025-06-17 15:03:41,521: INFO: common: created directory at: artifacts]
[2025-06-17 15:03:41,521: INFO: main: >>>>> stage Data transformation stage completed <<<<<<<

x==========x]
[2025-06-17 15:04:33,027: INFO: utils: NumExpr defaulting to 8 threads.]
[2025-06-17 15:04:33,943: INFO: main: >>>>>>>> stage Data ingestion stage started <<<<<<<<]
[2025-06-17 15:04:33,943: INFO: common: yaml file: config\config.yaml loaded successfully]
[2025-06-17 15:04:33,943: INFO: common: yaml file: params.yaml loaded successfully]
[2025-06-17 15:04:33,943: INFO: common: yaml file: schema.yaml loaded successfully]
[2025-06-17 15:04:33,943: INFO: common: created directory at: artifacts]
[2025-06-17 15:04:33,943: INFO: common: created directory at: artifacts/data_ingestion]
[2025-06-17 15:04:33,943: INFO: data_ingestion: File already exists]
[2025-06-17 15:04:33,943: INFO: main: >>>>> stage Data ingestion stage completed <<<<<<<

x==========x]
[2025-06-17 15:04:33,943: INFO: main: >>>>>>>> stage Data validation stage started <<<<<<<<]
[2025-06-17 15:04:33,943: INFO: common: yaml file: config\config.yaml loaded successfully]
[2025-06-17 15:04:33,960: INFO: common: yaml file: params.yaml loaded successfully]
[2025-06-17 15:04:33,962: INFO: common: yaml file: schema.yaml loaded successfully]
[2025-06-17 15:04:33,962: INFO: common: created directory at: artifacts]
[2025-06-17 15:04:33,962: INFO: common: created directory at: artifacts/data_validation]
[2025-06-17 15:04:33,975: INFO: main: >>>>> stage Data validation stage completed <<<<<<<

x==========x]
[2025-06-17 15:04:33,975: INFO: main: >>>>>>>> stage Data transformation stage started <<<<<<<<]
[2025-06-17 15:04:33,983: INFO: common: yaml file: config\config.yaml loaded successfully]
[2025-06-17 15:04:33,983: INFO: common: yaml file: params.yaml loaded successfully]
[2025-06-17 15:04:33,983: INFO: common: yaml file: schema.yaml loaded successfully]
[2025-06-17 15:04:33,983: INFO: common: created directory at: artifacts]
[2025-06-17 15:04:33,983: INFO: common: created directory at: artifacts/data_transformation]
[2025-06-17 15:04:33,991: INFO: main: >>>>> stage Data transformation stage completed <<<<<<<

x==========x]
[2025-06-17 15:05:26,866: INFO: utils: NumExpr defaulting to 8 threads.]
[2025-06-17 15:05:27,837: INFO: main: >>>>>>>> stage Data ingestion stage started <<<<<<<<]
[2025-06-17 15:05:27,846: INFO: common: yaml file: config\config.yaml loaded successfully]
[2025-06-17 15:05:27,846: INFO: common: yaml file: params.yaml loaded successfully]
[2025-06-17 15:05:27,846: INFO: common: yaml file: schema.yaml loaded successfully]
[2025-06-17 15:05:27,854: INFO: common: created directory at: artifacts]
[2025-06-17 15:05:27,854: INFO: common: created directory at: artifacts/data_ingestion]
[2025-06-17 15:05:27,854: INFO: data_ingestion: File already exists]
[2025-06-17 15:05:27,854: INFO: main: >>>>> stage Data ingestion stage completed <<<<<<<

x==========x]
[2025-06-17 15:05:27,854: INFO: main: >>>>>>>> stage Data validation stage started <<<<<<<<]
[2025-06-17 15:05:27,854: INFO: common: yaml file: config\config.yaml loaded successfully]
[2025-06-17 15:05:27,854: INFO: common: yaml file: params.yaml loaded successfully]
[2025-06-17 15:05:27,862: INFO: common: yaml file: schema.yaml loaded successfully]
[2025-06-17 15:05:27,862: INFO: common: created directory at: artifacts]
[2025-06-17 15:05:27,862: INFO: common: created directory at: artifacts/data_validation]
[2025-06-17 15:05:27,879: INFO: main: >>>>> stage Data validation stage completed <<<<<<<

x==========x]
[2025-06-17 15:05:27,879: INFO: main: >>>>>>>> stage Data transformation stage started <<<<<<<<]
[2025-06-17 15:05:27,879: INFO: common: yaml file: config\config.yaml loaded successfully]
[2025-06-17 15:05:27,879: INFO: common: yaml file: params.yaml loaded successfully]
[2025-06-17 15:05:27,886: INFO: common: yaml file: schema.yaml loaded successfully]
[2025-06-17 15:05:27,886: INFO: common: created directory at: artifacts]
[2025-06-17 15:05:27,929: INFO: common: created directory at: artifacts/data_transformation]
[2025-06-17 15:05:27,973: INFO: data_transformation: Splited data into training and test sets]
[2025-06-17 15:05:27,974: INFO: data_transformation: (1199, 12)]
[2025-06-17 15:05:27,974: INFO: data_transformation: (400, 12)]
[2025-06-17 15:05:27,974: INFO: main: >>>>> stage Data transformation stage completed <<<<<<<

x==========x]
[2025-06-17 15:28:57,303: INFO: utils: NumExpr defaulting to 8 threads.]
[2025-06-17 15:31:05,666: INFO: utils: NumExpr defaulting to 8 threads.]
[2025-06-17 15:31:06,818: INFO: main: >>>>>>>> stage Data ingestion stage started <<<<<<<<]
[2025-06-17 15:31:06,820: INFO: common: yaml file: config\config.yaml loaded successfully]
[2025-06-17 15:31:06,821: INFO: common: yaml file: params.yaml loaded successfully]
[2025-06-17 15:31:06,821: INFO: common: yaml file: schema.yaml loaded successfully]
[2025-06-17 15:31:06,823: INFO: common: created directory at: artifacts]
[2025-06-17 15:31:06,823: INFO: common: created directory at: artifacts/data_ingestion]
[2025-06-17 15:31:06,823: INFO: data_ingestion: File already exists]
[2025-06-17 15:31:06,828: INFO: main: >>>>> stage Data ingestion stage completed <<<<<<<

x==========x]
[2025-06-17 15:31:06,828: INFO: main: >>>>>>>> stage Data validation stage started <<<<<<<<]
[2025-06-17 15:31:06,830: INFO: common: yaml file: config\config.yaml loaded successfully]
[2025-06-17 15:31:06,830: INFO: common: yaml file: params.yaml loaded successfully]
[2025-06-17 15:31:06,832: INFO: common: yaml file: schema.yaml loaded successfully]
[2025-06-17 15:31:06,832: INFO: common: created directory at: artifacts]
[2025-06-17 15:31:06,832: INFO: common: created directory at: artifacts/data_validation]
[2025-06-17 15:31:06,843: INFO: main: >>>>> stage Data validation stage completed <<<<<<<

x==========x]
[2025-06-17 15:31:06,843: INFO: main: >>>>>>>> stage Data transformation stage started <<<<<<<<]
[2025-06-17 15:31:06,844: INFO: common: yaml file: config\config.yaml loaded successfully]
[2025-06-17 15:31:06,844: INFO: common: yaml file: params.yaml loaded successfully]
[2025-06-17 15:31:06,844: INFO: common: yaml file: schema.yaml loaded successfully]
[2025-06-17 15:31:06,844: INFO: common: created directory at: artifacts]
[2025-06-17 15:31:06,844: INFO: common: created directory at: artifacts/data_transformation]
[2025-06-17 15:31:06,917: INFO: data_transformation: Splited data into training and test sets]
[2025-06-17 15:31:06,919: INFO: data_transformation: (1199, 12)]
[2025-06-17 15:31:06,919: INFO: data_transformation: (400, 12)]
[2025-06-17 15:31:06,919: INFO: main: >>>>> stage Data transformation stage completed <<<<<<<

x==========x]
[2025-06-17 15:31:06,919: INFO: main: >>>>>> stage Model Trainer stage started <<<<<<]
[2025-06-17 15:31:06,919: INFO: common: yaml file: config\config.yaml loaded successfully]
[2025-06-17 15:31:06,919: INFO: common: yaml file: params.yaml loaded successfully]
[2025-06-17 15:31:06,919: INFO: common: yaml file: schema.yaml loaded successfully]
[2025-06-17 15:31:06,919: INFO: common: created directory at: artifacts]
[2025-06-17 15:31:06,919: INFO: common: created directory at: artifacts/model_trainer]
[2025-06-17 15:31:07,075: INFO: main: >>>>>> stage Model Trainer stage completed <<<<<<

x==========x]
